Workbook

Sheet Calculations
A1: VESTAS - HILUX DUAL CAB (BH01) - estimate from photo
A3: Item | B3: Width m | C3: Height m | D3: Qty | E3: m2
A4: Vestas logo (front door) | B4: 0.7 | C4: 0.2 | D4: 2 | E4: =B4*C4*D4
A5: BH01 call ID (rear door) - REFLECTIVE | B5: 0.3 | C5: 0.22 | D5: 2 | E5: =B5*C5*D5
A6: Total decal area | E6: =E4+E5
A8: Logo - MPI 1105 w/ DOL 1460 (1.37m stock)
A9: Logo 0.70 x 0.20 -> 0.25m per side incl. margins; 2 sides = 0.50 lm (WORKSHEET!I10), 0.685 m2
A10: Call ID - 3M 680CR reflective w/ 8519 lustre (1.22m stock, $72/m2)
A11: Both plates 0.30 + 0.30 = 0.60m wide nest on one row, 0.22 + margin = 0.25 lm (WORKSHEET!I18), 0.305 m2
A13: Scale: front door ~0.95m wide in photo -> logo ~0.70m (+/-15%). Plate size is rough.
A14: Assumed: 1 vehicle, both sides identical, no rear/tailgate/bonnet graphics, 1 hr install, no freight
A15: Note: STOCKS tab says DOL 1460 is listed for use with MPI 1005 (old); 1105 normally pairs with 6460. Used 1105/1460 as instructed.
A16: Master sheet note: WORKSHEET!I9 was hard-coded 0 (kills kiss-cut material); replaced with formula in this copy

Sheet SUB Price
B5: Nathan's Price | C5: Hours - person (worked out by $128 per hour) | D5: 30% m/up | E5: Hours - person (worked out by $128 per hour) | F5: 40% m/up | G5: Hours - person (worked out by $128 per hour)
A6: Yaris | B6: 1710 | C6: =B6/128 | D6: =B6*1.3 | E6: =D6/128 | F6: =B6*1.4 | G6: =F6/128
A7: Carolla | B7: 1710 | C7: =B7/128 | D7: =B7*1.3 | E7: =D7/128 | F7: =B7*1.4 | G7: =F7/128
A8: Commuter | B8: 1890 | C8: =B8/128 | D8: =B8*1.3 | E8: =D8/128 | F8: =B8*1.4 | G8: =F8/128
A9: Coaster | B9: 2295 | C9: =B9/128 | D9: =B9*1.3 | E9: =D9/128 | F9: =B9*1.4 | G9: =F9/128

Sheet Freight
A1: TOLL PRICES
A2: 1 box of 45.7m of Vinyl = 24kg
A3: (0.7 kg per metre)
A5: Consignment - $11
A6: Plus 15% surcharge
A9: OFF PEAK
A10: Sydney Area - $1.38 / kg
A11: Brisbane Area - $3.40 / kg
A12: Perth Area - $2.95 / kg
A14: OVERNIGHT
A15: Sydney Area - $3.68 / kg
A16: Brisbane Area - $8.70 / kg
A17: Perth Area - $12.78 / kg

Sheet Avery Prices
A1: Name | B1: LABEL CONCEPTS P/L(90Days) - TELSTRA
L2: Increased Pricing
A3: Row Labels | B3: Description | C3: UM | D3: Width (m) | E3: Length (m) | F3: Current price | G3: Increase % | H3: New price
A4: M5332 | B4: MPI 1005 SC EA RS GW REM | C4: M2 | D4: 1.372 | E4: 45.7 | F4: 8.42 | G4: 0 | H4: 8.42
A5: M5046 | B5: DOL 1460 GL CL PER PET | C5: M2 | D5: 1.372 | E5: 45.7 | F5: 8.42 | G5: 0.025 | H5: 8.63
A6: TC1934 | B6: DOL 1360 GL TRANS PER KR | C6: M2 | D6: 1.372 | E6: 45.7 | F6: 8.44 | G6: 0.045 | H6: 8.82
A7: M3511 | B7: MPI 1005 SC GO LTR PE | C7: M2 | D7: 1.372 | E7: 45.7 | F7: 8.42 | G7: 0 | H7: 8.42
G9: Current Pack pricing = $1055.86
G10: New pack pricing = $1069.03 ($13.17)
A13: Name | B13: LABEL CONCEPTS PTY LTD (STANDARD ACCOUNT)
A15: Row Labels | B15: Description | C15: UM | D15: Width (m) | E15: Length (m) | F15: Current price | G15: Increase % | H15: New price
A16: AR9250001 | B16: 2700/337A GUN GREY JAYCO | C16: M2 | D16: 1.23 | E16: 50 | F16: 9.45 | G16: 0.015 | H16: 9.59 | I16: =(1.23*50)*H16
A17: MSY5106 | B17: 2700/277B SILVER JAYCO 1 | C17: M2 | D17: 1.23 | E17: 50 | F17: 9.45 | G17: 0.015 | H17: 9.59
A18: MSY5130 | B18: 2700/280B CHARCL JAYCO | C18: M2 | D18: 1.23 | E18: 50 | F18: 9.45 | G18: 0.015 | H18: 9.59
A19: M5332 | B19: MPI 1005 SC EA RS GW REM | C19: M2 | D19: 1.372 | E19: 45.7 | F19: 8.42 | G19: 0 | H19: 8.42
A20: M3511 | B20: MPI 1005 SC GO LTR PE | C20: M2 | D20: 1.372 | E20: 45.7 | F20: 8.42 | G20: 0 | H20: 8.42
A21: MUC8754 | B21: DOL 4300 GL A/GRF PER KR | C21: M2 | D21: 1.37 | E21: 50 | F21: 10.49 | G21: 0.035 | H21: 10.86
A22: MSY5155 | B22: 2700/276B RYLBLU JAYCO | C22: M2 | D22: 1.23 | E22: 50 | F22: 9.45 | G22: 0.015 | H22: 9.59
A23: AS1280001 | B23: 2700/339A GOLD | C23: M2 | D23: 1.23 | E23: 50 | F23: 9.45 | G23: 0.015 | H23: 9.59
A24: 413747A60R | B24: DOL 1480 MATT CL PER KR | C24: M2 | D24: 1.372 | E24: 45.7 | F24: 12.77 | G24: 0.045 | H24: 13.34
A25: TC3054 | B25: 2600/460A ORANGE JAYCO | C25: M2 | D25: 1.23 | E25: 50 | F25: 9.45 | G25: 0.015 | H25: 9.59
A26: 41084 | B26: MPI 2105 GL WH EA RS LTR | C26: M2 | D26: 1.372 | E26: 45.7 | F26: 6.08 | G26: 0.035 | H26: 6.29
A27: M5046 | B27: DOL 1460 GL CL PER PET | C27: M2 | D27: 1.372 | E27: 45.7 | F27: 12.77 | G27: 0.045 | H27: 13.34
A28: AV9390001 | B28: 2600/504A GREEN JAYCO | C28: M2 | D28: 1.23 | E28: 50 | F28: 9.45 | G28: 0.015 | H28: 9.59
A29: MUB9308 | B29: FASFITI GL CLR PER KR | C29: M2 | D29: 1.23 | E29: 50 | F29: 9.69 | G29: 0.035 | H29: 10.03
A30: AS3280001 | B30: 2700/342A COPPER M JAYCO | C30: M2 | D30: 1.23 | E30: 50 | F30: 9.45 | G30: 0.015 | H30: 9.59
A31: M3790 | B31: 400 GLOSS WHITE PERM PE | C31: EA | D31: 1 | E31: 760 | F31: 1.92 | G31: 0.02 | H31: 1.96
A32: TC1934 | B32: DOL 1360 GL TRANS PER KR | C32: M2 | D32: 1.372 | E32: 45.7 | F32: 11.61 | G32: 0.045 | H32: 12.13
A33: BB4320001 | B33: 2700/381A BLACK M JAYCO | C33: M2 | D33: 1.23 | E33: 50 | F33: 9.45 | G33: 0.015 | H33: 9.59
A34: 3790 | B34: SERILUX 72100 GW PER PE | C34: EA | D34: 1 | E34: 760 | F34: 1.92 | G34: 0.02 | H34: 1.96
A35: TC1942 | B35: DOL 1060 GL TRANS PER KR | C35: M2 | D35: 1.372 | E35: 45.7 | F35: 10.63 | G35: 0.045 | H35: 11.11
A36: 1226 | B36: SERILUX 72101 MW REM KR | C36: EA | D36: 1 | E36: 760 | F36: 2.22 | G36: 0.02 | H36: 2.26
A37: M41027 | B37: DOL 1360 GL TRAN PER PET | C37: M2 | D37: 1.372 | E37: 45.7 | F37: 11.61 | G37: 0.045 | H37: 12.13
A38: 41121 | B38: MPI 2105 GL WH EA RS LTR | C38: M2 | D38: 1.524 | E38: 45.7 | F38: 6.08 | G38: 0.035 | H38: 6.29
A39: MUC9505 | B39: DOL 2000 GL TRANS PER KR | C39: M2 | D39: 1.37 | E39: 50 | F39: 5.39 | G39: 0.04 | H39: 5.61
A40: MYB2882 | B40: DOL 3100 MT TRANS PER KR | C40: M2 | D40: 1.37 | E40: 50 | F40: 2.35 | G40: 0.045 | H40: 2.46
A41: M29304 | B41: DOL 1060 GL TRAN PER PET | C41: M2 | D41: 1.524 | E41: 45.7 | F41: 10.63 | G41: 0.045 | H41: 11.11
A42: AV6850001 | B42: 2700/357A BR BLU M JAYCO | C42: M2 | D42: 1.23 | E42: 50 | F42: 9.45 | G42: 0.015 | H42: 9.59
A43: M2797 | B43: 440 GLOSS TRANSP PERM PE | C43: EA | D43: 1 | E43: 760 | F43: 1.87 | G43: 0.02 | H43: 1.91
A44: MUD2806 | B44: DOL 2100 MT TRANS PER KR | C44: M2 | D44: 1.37 | E44: 50 | F44: 5.39 | G44: 0.04 | H44: 5.61
...

Sheet STOCKS from QP
A1: STOCK CODE | B1: DESCRIPTION | C1: SIZE | D1: PRICE M2 (inc M/Up) | E1: NOTES | F1: SUPPLIER
A2: MPI1005629 | B2: MPI 1105 Easy Apply (NEW) | C2: 1370mm or 1520mm x 45.7m | E2: An Easy Apply stock used on vehicle wraps | F2: Avery
A3: DOLPOLY | B3: DOL 6460 Polyyurethane Overlaminate | C3: 1370mm or 1520mm x 45.7m | E3: Gloss conformable lamiante to suit MPI 1105 | F3: Avery
A4: 6460PAC | B4: MPI 1105 EARS & 6460 Laminate | C4: As above | D4: 21 | E4: Pack Special - Telstra | F4: Avery
A5: 2105EA | B5: MPI 2105 Easy Apply Gloss Permanent | C5: 1370mm x 45.7m | E5: An Easy Apply stock used on flat areas | F5: Avery
A6: DOL2000 | B6: DOL 2000 Budget Clear Laminate | C6: 1370mm x 45.7m | E6: Gloss Laminate to suit MPI 2105 | F6: Avery
A7: DOL2100 | B7: DOL 2100 Matte Laminate | C7: 1370mm x 45.7m | E7: Matt Laminate to suit MPI 2105 | F7: Avery
A8: MPI2006 | B8: MPI2006 Gloss Permanent High Tack | C8: 1370mm x 25m or 45.7m | E8: Gloss White Vinyl with an aggressive adhesive
A9: DOL1060 | B9: DOL 1060 Gloss Overlaminate | C9: 1370mm x 45.7m | E9: Only to be used with MPI 1005 Easy Apply (OLD)
A10: DOL1080 | B10: DOL 1080 Matte Laminate | C10: 1370mm x 45.7m | E10: Only to be used with MPI 1005 Easy Apply (OLD)
A11: DOL1360 | B11: DOL 1360 3D Clear Laminate | C11: 1370mm x 45.7m | E11: Only to be used with MPI 1005 Easy Apply (OLD)
A12: DOL1460 | B12: DOL 1460 3D High Gloss Super Conformable | C12: 1370mm x 45.7m | E12: Only to be used with MPI 1005 Easy Apply (OLD)
A13: DOL1480 | B13: DOL 1480 3D Matt Super Conformable | C13: 1370mm x 45.7m | E13: Only to be used with MPI 1005 Easy Apply (OLD)
A14: DOL43001 | B14: DOL 4300 Overlaminate | C14: 1370mm x 45.7m | E14: Anti Graffiti Laminate (BP / Rear of PTV Bus)
A15: FASFITI | B15: Fasfiti Laminate | C15: 1220mm x 45.7m | E15: Anti Graffiti Laminate (BP) - can be slit
A16: 680CR-10 | B16: 3M 680CR White Reflective | C16: 1220mm x 45.7m | E16: Conformable white reflective stock - Warranty | F16: Halifax Vogal
A17: 8519LUSTRE | B17: 3M 8519 Lustre Laminate | C17: 1370mm x 45.7m | E17: Laminate to suit 680CR - Satin finish - when ordering slit to 1210mm wide | F17: Halifax Vogal
A18: 3MIJ180 | B18: 3M 180CV3 Cast Gloss White with Comply | C18: 1370mm x 45.7m | E18: An Easy Apply stock used on vehicle wraps - not suitable during cold weather (3M's alternative to Avery's MPI)1105
A19: 8518GLOSS | B19: 3M 8518 Gloss Laminate | C19: 1370mm x 45.7m | E19: Gloss conformable lamiante to suit 3M180C
A20: ONEWAYAUTO | B20: Oneway Vision Autoview | C20: 1370mm x 50m | E20: Perforated Window Vinyl
A21: ONEWAYLAM | B21: Oneway Vision CurvaLam | C21: 1370mm x 30m | E21: Gloss Laminate to suit Autoview
A22: APPTAPE | B22: NT100 Application Tape | C22: 1220mm x 90m | D22: 1.8 | E22: Standard Application Tape
A23: APPTAPECLRNT210 | B23: Transparent Application Tape @1220 | C23: 1220mm x | E23: Clear Application Tape
A24: MAGNET.9 | B24: Magnetic 0.9mm Gloss White | E24: Used for Car decals - Can screen print direct or mount a digital print
A25: GLOSSCLEAR2797 | B25: Serilux 70100 Gloss Clear Pemanent | C25: 760 x 1000mm | E25: 3 year Vinyl used for Screen Printing
A26: GLWHPERA | B26: Serilux 72100 Gloss White Pemanent | C26: 760 x 1000mm | E26: 3 year Vinyl used for Screen Printing
A27: MATWHIPERM | B27: Serilux 72101 Matt White Pemanent | C27: 760 x 1000mm | E27: 3 year Vinyl used for Screen Printing
A28: MATWHREM | B28: Serilux 7201 Matt White Removeable | C28: 760 x 1000mm | E28: 3 year Vinyl used for Screen Printing

Sheet Vutek - Std (FSPLIT)
A1: Areas you may need to alter at times | D1: Areas you need to enter data
A3: Customer/Contact: | B3: Vestas | D3: Rep:
A4: Job Description: | B4: Hilux dual cab - door logos both sides (Vestas + BH01) | D4: Size: | E4: 2 x (0.70x0.20 logo + 0.30x0.22 plate)
A5: Material: | B5: Logo: MPI 1105 w/ DOL 1460; Call ID: 3M 680CR reflective w/ 8519 (kiss cut) | D5: Installer:
A8: Quantity | B8: 1 | C8: 1 | D8: 10 | E8: 1
A10: ART (Hours) | B10: 1 | C10: 1 | D10: 1 | E10: 1
A11: Set Up ($85/hr) | B11: 0 | D11: =85*D10 | E11: 85
A12: File set up/template $170 plus GST. | B12: 0 | D12: 170
A13: MATERIAL
A14: =WORKSHEET!A7 | C14: =WORKSHEET!C12+WORKSHEET!I12 | D14: =WORKSHEET!D12+WORKSHEET!J12 | E14: =WORKSHEET!E12+WORKSHEET!K12
A15: 680 w/ 8519 | C15: =WORKSHEET!C20+WORKSHEET!I20 | D15: =WORKSHEET!D20+WORKSHEET!J20 | E15: =WORKSHEET!E20+WORKSHEET!K20
A16: Perf w/ Lam | C16: =WORKSHEET!C28+WORKSHEET!I28 | D16: =WORKSHEET!D28+WORKSHEET!J28 | E16: =WORKSHEET!E28+WORKSHEET!K28
A17: 4 METRES EXT | C17: =B17 | D17: =C17 | F17: All stocks
A18: APP TAPE min | C18: 20 | D18: 20 | E18: 20 | F18: Min charge
A19: Application Tape ($1.8 per m2) | D19: =(WORKSHEET!J13+WORKSHEET!J21+WORKSHEET!J29)*1.8 | E19: =(WORKSHEET!K13+WORKSHEET!K21+WORKSHEET!K29)*1.8
A20: PRINT
A21: Set Up ($125) | C21: 125 | D21: 125 | E21: 125
A22: Run Time ($90/hr @ 45m per hour) | C22: =((WORKSHEET!C13+WORKSHEET!C21+WORKSHEET!C29+WORKSHEET!I13+WORKSHEET!I21+WORKSHEET!I29)/45)*90 | D22: =((WORKSHEET!D13+WORKSHEET!D21+WORKSHEET!D29+WORKSHEET!J13+WORKSHEET!J21+WORKSHEET!J29)/45)*90 | E22: =((WORKSHEET!E13+WORKSHEET!E21+WORKSHEET!E29+WORKSHEET!K13+WORKSHEET!K21+WORKSHEET!K29)/45)*90
A23: INK
A24: Ink Usage ($3.34 per Sq Metre) | C24: =(WORKSHEET!C9+WORKSHEET!C17+WORKSHEET!C25+WORKSHEET!I9+WORKSHEET!I17+WORKSHEET!I25)*3.34 | D24: =(WORKSHEET!D9+WORKSHEET!D17+WORKSHEET!D25+WORKSHEET!J9+WORKSHEET!J17+WORKSHEET!J25)*3.34 | E24: =(WORKSHEET!E9+WORKSHEET!E17+WORKSHEET!E25+WORKSHEET!K9+WORKSHEET!K17+WORKSHEET!K25)*3.34
A25: FINISHING
A26: Laminate Set up $45 | C26: 45 | D26: 45 | E26: 45
A27: Laminate ($90/hr @ 45m per hour) | C27: =((WORKSHEET!C13+WORKSHEET!C21+WORKSHEET!C29+WORKSHEET!I13+WORKSHEET!I21+WORKSHEET!I29)/45)*90 | D27: =((WORKSHEET!D13+WORKSHEET!D21+WORKSHEET!D29+WORKSHEET!J13+WORKSHEET!J21+WORKSHEET!J29)/45)*90 | E27: =((WORKSHEET!E13+WORKSHEET!E21+WORKSHEET!E29+WORKSHEET!K13+WORKSHEET!K21+WORKSHEET!K29)/45)*90
A28: ZUND Set up $45 | B28: 45 | C28: 45 | D28: 45 | E28: 45
A29: ZUND - Basic Through cut ($105/hr @ 45m per hour) | B29: =((WORKSHEET!B13+WORKSHEET!B21+WORKSHEET!B29)/45)*105 | C29: =((WORKSHEET!C13+WORKSHEET!C21+WORKSHEET!C29)/45)*105 | D29: =((WORKSHEET!D13+WORKSHEET!D21+WORKSHEET!D29)/45)*105 | E29: =((WORKSHEET!E13+WORKSHEET!E21+WORKSHEET!E29)/45)*105
A30: ZUND - Basic Kiss & Through cut or Pen & Through cut ($105/hr @ 15m per hour) | B30: =((WORKSHEET!H13+WORKSHEET!H21+WORKSHEET!H29)/WORKSHEET!H31)*105 | C30: =((WORKSHEET!I13+WORKSHEET!I21+WORKSHEET!I29)/WORKSHEET!I31)*105 | D30: =((WORKSHEET!J13+WORKSHEET!J21+WORKSHEET!J29)/WORKSHEET!J31)*105 | E30: =((WORKSHEET!K13+WORKSHEET!K21+WORKSHEET!K29)/WORKSHEET!K31)*105
A31: Weeding ($65/hr @ 2 sets per hour) | C31: =(C8/2)*65 | D31: =(D8/2)*65 | F31: 7 UP = 15 Mins per sheet.
A32: SET UP APP TAPE | C32: 45 | D32: 45 | F32: Set up added
A33: Lam App Tape ($90/hr @ 25m per hour) | C33: =((WORKSHEET!I13+WORKSHEET!I21+WORKSHEET!I29)/25)*90 | D33: =((WORKSHEET!J13+WORKSHEET!J21+WORKSHEET!J29)/25)*90 | F33: Changed to 25 lm per hour
A34: Hand Trim ($12/lm) | C34: =(WORKSHEET!I13+WORKSHEET!I21+WORKSHEET!I29)*12 | D34: =(WORKSHEET!J13+WORKSHEET!J21+WORKSHEET!J29)*12 | F34: Changed to $12 per L/M
E35: 200
A36: Packing ($15/per set) | B36: =(75*5)/2 | C36: 15 | D36: 30 | E36: 30 | F36: $15 per set
A38: DeliveryMin $45 (QLD - $3.4 per kg plus $12 per c/s + 15%surcharge) (0.7kg per LM) | C38: 0 | D38: 45 | E38: 65
A40: SUB TOTAL | B40: =SUM(B10:B39) | C40: =SUM(C10:C39) | D40: =SUM(D10:D39) | E40: =SUM(E10:E39)
A41: 35% mark up | B41: =B40*0.35 | C41: =C40*0.35 | D41: =D40*0.35 | E41: =E40*0.35
A42: TOTAL | B42: =B40+B41 | C42: =C40+C41 | D42: =D40+D41 | E42: =E40+E41 | G42: =B42/3
A43: Unit Price | B43: =B42/B8 | C43: =C42/C8 | D43: =D42/D8 | E43: =E42/E8
A44: Installation ($125/hr) | B44: =300*1.3 | C44: =125*1*1.4 | D44: =380*1.4 | E44: =1.4*300 | H44: 798 | I44: =550*1.4 | J44: =H44+I44
A45: Total installed price | B45: =B44+B43 | C45: =C44+C43 | D45: =D44+D43 | E45: =E44+E43 | H45: 728 | I45: =480*1.4 | J45: =H45+I45
H46: 728 | I46: =480*1.4 | J46: =H46+I46
...

Sheet WORKSHEET
A2: THROUGH CUT | G2: KISS CUT
A4: QUANTITY | B4: 1 | C4: 5 | D4: 10 | E4: 20 | G4: QUANTITY | H4: 100 | I4: 500 | J4: 1000 | K4: 12
A6: MATERIAL NAME | B6: WIDE | C6: SQ PRICE | G6: MATERIAL NAME | H6: WIDE | I6: SQ PRICE
A7: MPI 1105 w/ 1460z & 6460 | B7: 1.37 | C7: 28 | E7: =(B7*4)*C7 | G7: MPI 1105 w/ 1460 | H7: 1.37 | I7: 28 | K7: =(H7*4)*I7
A9: Square used | B9: =(B7*B10)*B11 | C9: =(B7*C10)*C11 | D9: =(B7*D10)*D11 | E9: =(B7*E10)*E11 | G9: Square used | H9: =(H7*H10)*H11 | I9: =(H7*I10)*I11 | J9: =(H7*J10)*J11 | K9: =(H7*K10)*K11
A10: Lineal Metres | B10: 0 | C10: 0 | D10: 0 | E10: 0 | G10: Lineal Metres | H10: 1 | I10: 0.5 | J10: 0 | K10: 1
A11: RUN | B11: 0 | C11: 0 | D11: 0 | E11: 0 | G11: RUN | H11: 1 | I11: 1 | J11: 5 | K11: 1
A12: PRICE | B12: =(B9*C7) | C12: =(C9*C7) | D12: =(D9*C7) | E12: =(E9*C7) | H12: =(H9*I7) | I12: =(I9*I7) | J12: =(J9*I7) | K12: =(I7*K9)
B13: =B11*B10 | C13: =C11*C10 | D13: =D11*D10 | E13: =E11*E10 | H13: =H11*H10 | I13: =I11*I10 | J13: =J11*J10 | K13: =K11*K10
A14: MATERIAL NAME | B14: WIDE | C14: SQ PRICE | G14: MATERIAL NAME | H14: WIDE | I14: SQ PRICE
A15: 3M 680 CR w/ 8519 | B15: 1.22 | C15: 72 | E15: =(B15*4)*C15 | G15: 3M 680 CR w/ 8519 | H15: 1.22 | I15: 72 | K15: =(H15*4)*I15
A17: Square used | B17: =(B15*B18)*B19 | C17: =(B15*C18)*C19 | D17: =(B15*D18)*D19 | E17: =(B15*E18)*E19 | G17: Square used | H17: =(H15*H18)*H19 | I17: =(H15*I18)*I19 | J17: =(H15*J18)*J19 | K17: =(H15*K18)*K19
A18: Lineal Metres | B18: 0 | C18: 0 | G18: Lineal Metres | H18: 0 | I18: 0.25 | J18: 0 | K18: 0
A19: RUN | B19: 0 | C19: 0 | D19: 0 | E19: 0 | G19: RUN | H19: 1 | I19: 1 | J19: 1 | K19: 1
A20: PRICE | B20: =(B17*C15) | C20: =(C17*C15) | D20: =(D17*C15) | E20: =(E17*C15) | H20: =(H17*I15) | I20: =(I17*I15) | J20: =(J17*I15) | K20: =(K17*I15)
B21: =B19*B18 | C21: =C19*C18 | D21: =D19*D18 | E21: =E19*E18 | H21: =H19*H18 | I21: =I19*I18 | J21: =J19*J18 | K21: =K19*K18
A22: MATERIAL NAME | B22: WIDE | C22: SQ PRICE | G22: MATERIAL NAME | H22: WIDE | I22: SQ PRICE
A23: Perf of some name w/ Clear | B23: 1.37 | C23: 36 | E23: =(B23*4)*C23 | G23: Perf of some name w/ Clear | H23: 1.37 | I23: 36 | K23: =(H23*4)*I23
A25: Square used | B25: =(B23*B26)*B27 | C25: =(B23*C26)*C27 | D25: =(B23*D26)*D27 | E25: =(B23*E26)*E27 | G25: Square used | H25: =(H23*H26)*H27 | I25: =(H23*I26)*I27 | J25: =(H23*J26)*J27 | K25: =(H23*K26)*K27
A26: Lineal Metres | G26: Lineal Metres
A27: RUN | G27: RUN
A28: PRICE | B28: =(B25*C23) | C28: =(C25*C23) | D28: =(D25*C23) | E28: =(E25*C23) | H28: =(H25*I23) | I28: =(I25*I23) | J28: =(J25*I23) | K28: =(K25*I23)
B29: =B27*B26 | C29: =C27*C26 | D29: =D27*D26 | E29: =E27*E26 | H29: =H27*H26 | I29: =I27*I26 | J29: =J27*J26 | K29: =K27*K26
G31: ZUND SPEED - amend when needed | H31: 25 | I31: 25 | J31: 25 | K31: 25
G37: ZUND Speeds | H37: M per hrs
G38: kiss cut & through cut - Intricut / small | H38: 9 lm
G39: kiss cut & through cut - large | H39: 15 lm
G40: kiss cut std | H40: 25 lm

Sheet STOCK
A1: SUPPLIER | B1: Stock | C1: We charge out - per square metre | D1: Notes
A2: AVERY | B2: 1105 w/ 6460 pac | C2: 31 | D2: Bonnets / Roof
A3: AVERY | B3: 1105 w/ 1460z pac | C3: 24 | D3: Std vehicle wrap
A4: AVERY | B4: 1106 w/ 1460z pac | C4: 31 | D4: High tack version of 1105
A5: AVERY | B5: 1105 w/ 1060Z pac | D5: Thicker lam for truck panels - ease of install
A6: AVERY | B6: 2105 w/ 2000 | C6: =(9+6.5)*1.15 | D6: Door decals - simple flat areas - Supagas
A7: AVERY | B7: 2106 w/ 2000 | D7: High tack version of 2105 - Supagas
A8: AVERY | B8: 2900 w/ 2960 (Gloss) | D8: Decals / Sticker requests
A9: AVERY | B9: 2900 w/ 2980 (Matt) | D9: Decals / Sticker requests
A10: AVERY | B10: 2904 (rem) w/ 2960 (Gloss) | D10: Decals / Sticker requests
A11: AVERY | B11: 2904 (rem) w/ 2980 (Matt) | D11: Decals / Sticker requests
A12: AVERY | B12: 2923 (HT) w/ 2960 (Gloss) | D12: Decals / Sticker requests
A13: AVERY | B13: 2923 (HT) w/ 2980 (Matt) | D13: Decals / Sticker requests
A14: AVERY | B14: DOL 4530 (Anti Graf) - SL4530 | C14: 752.51 | D14: Overlaminate stock code now
B15: Clarification:
A41: LABEL CONCEPTS PTY L | B41: 333113 | C41: A002539 | D41: MPI 2105 GL WH EA RS LTR_1.372M X 45.7M | E41: =IFERROR(VLOOKUP(C41,'[1]June GSAC'!C:L,10,0),0) | F41: =IFERROR(VLOOKUP(C41,'[1]Jul GSAC'!C:L,10,0),0)
A42: LABEL CONCEPTS PTY L | B42: 333113 | C42: A005632 | D42: DOL 6460 GC PU PER PET_1.372M X 45.7M | E42: 1063.96 | F42: 1095.88
A43: LABEL CONCEPTS PTY L | B43: 333113 | C43: A006091 | D43: MPI 1105 EA RS LTR GW PE_1.524M X 45.7M | E43: 618.83 | F43: 637.39
A44: LABEL CONCEPTS PTY L | B44: 333113 | C44: A006094 | D44: MPI 1105 EA RS LTR GW PE_1.372M X 45.7M | E44: 553.96 | F44: 570.58 | G44: 1460zpac2 - 1520
A45: LABEL CONCEPTS PTY L | B45: 333113 | C45: A006170 | D45: DOL 1460Z GL TRAN PER PET_1.524M X 45.7M | E45: 767.87 | F45: 790.91 | G45: =F45+F43
A46: LABEL CONCEPTS PTY L | B46: 333113 | C46: A006171 | D46: DOL 1460Z GL TRAN PER PET_1.372M X 45.7M | E46: 693.27 | F46: 714.07 | G46: 6460zpac2 - 1520
A47: LABEL CONCEPTS PTY L | B47: 333113 | C47: CE3370264 | D47: SL 4530 ANTI GRAFFITI_1.37M X 50M | E47: 752.51 | F47: 752.51 | G47: 1849 | H47: =G47*11 | I47: =H47*1.15
A48: LABEL CONCEPTS PTY L | B48: 333113 | C48: CE3600012 | D48: DOL 2000 GL TRANS PER KR_1.37M X 45M | E48: =IFERROR(VLOOKUP(C48,'[1]June GSAC'!C:L,10,0),0) | F48: =IFERROR(VLOOKUP(C48,'[1]Jul GSAC'!C:L,10,0),0)
A49: LABEL CONCEPTS PTY L | B49: 333113 | C49: CE581.760 | D49: 400 GLOSS WHITE PERM KR1000MM X 760MM SHEET | E49: =IFERROR(VLOOKUP(C49,'[1]June GSAC'!C:L,10,0),0) | F49: =IFERROR(VLOOKUP(C49,'[1]Jul GSAC'!C:L,10,0),0)
G51: =(G47/1.37)*1.52
C53: The 3m product we recommend for anti graffiti is the 8993 hi gloss 1370x50m
C55: Roll price is $1344.00
C56: $26.88 per lm
C57: Ex gst

Sheet UPDATES
A1: Hi All,
A3: Please see below updated rates for all quotes - note these are the bare minimum to charge, and particularly on small decal runs etc, I would expect you to add extra to cover the messing around.
A6: New item:
A8: On all quotes, charge a separate amount of $94 plus GST for File Set up. This is shown to clients as a separate, one off charge to their quotation.
A10: Art/Pre-Press
A11: The $85 is a bare minimum for one hours Pre-Press work, that has no design.
A12: Note for complex jobs, this should be charged on the estimated number of hours required to design, edit and set up for print - many hundreds of dollars should be charged for full wraps, with no design.
A14: Stock
A15: Allow 4 linear metres for waste - take up on the roller, collection at the end.
A16: Again, this is a minimum - for larger run work, allow 5% waste on top for other errors.
A18: Print
A19: Set up fee now $125
... A46: Director
A47: M | B47: 0418 424 231
A48: labelconcepts.com.au
